{1} setUpClass (octavia_tempest_plugin.tests.scenario.v2.test_listener.ListenerScenarioTest) [0.000000s] ... FAILED

Captured traceback:
~~~~~~~~~~~~~~~~~~~
    Traceback (most recent call last):
      File "/usr/local/lib/python2.7/dist-packages/tempest/test.py", line 172, in setUpClass
        six.reraise(etype, value, trace)
      File "/usr/local/lib/python2.7/dist-packages/tempest/test.py", line 165, in setUpClass
        cls.resource_setup()
      File "/usr/local/lib/python2.7/dist-packages/octavia_tempest_plugin/tests/scenario/v2/test_listener.py", line 53, in resource_setup
        CONF.load_balancer.lb_build_timeout)
      File "/usr/local/lib/python2.7/dist-packages/octavia_tempest_plugin/tests/waiters.py", line 78, in wait_for_status
        raise exceptions.UnexpectedResponseCode(message)
    tempest.lib.exceptions.UnexpectedResponseCode: Unexpected response code received
    Details: (ListenerScenarioTest:setUpClass) show_loadbalancer provisioning_status updated to an invalid state of ERROR
    
{3} setUpClass (octavia_tempest_plugin.tests.scenario.v2.test_l7rule.L7RuleScenarioTest) [0.000000s] ... FAILED

Captured traceback:
~~~~~~~~~~~~~~~~~~~
    Traceback (most recent call last):
      File "/usr/local/lib/python2.7/dist-packages/tempest/test.py", line 172, in setUpClass
        six.reraise(etype, value, trace)
      File "/usr/local/lib/python2.7/dist-packages/tempest/test.py", line 165, in setUpClass
        cls.resource_setup()
      File "/usr/local/lib/python2.7/dist-packages/octavia_tempest_plugin/tests/scenario/v2/test_l7rule.py", line 52, in resource_setup
        CONF.load_balancer.lb_build_timeout)
      File "/usr/local/lib/python2.7/dist-packages/octavia_tempest_plugin/tests/waiters.py", line 78, in wait_for_status
        raise exceptions.UnexpectedResponseCode(message)
    tempest.lib.exceptions.UnexpectedResponseCode: Unexpected response code received
    Details: (L7RuleScenarioTest:setUpClass) show_loadbalancer provisioning_status updated to an invalid state of ERROR
    
{0} setUpClass (octavia_tempest_plugin.tests.scenario.v2.test_amphora.AmphoraScenarioTest) [0.000000s] ... FAILED

Captured traceback:
~~~~~~~~~~~~~~~~~~~
    Traceback (most recent call last):
      File "/usr/local/lib/python2.7/dist-packages/tempest/test.py", line 172, in setUpClass
        six.reraise(etype, value, trace)
      File "/usr/local/lib/python2.7/dist-packages/tempest/test.py", line 165, in setUpClass
        cls.resource_setup()
      File "/usr/local/lib/python2.7/dist-packages/octavia_tempest_plugin/tests/scenario/v2/test_amphora.py", line 54, in resource_setup
        CONF.load_balancer.lb_build_timeout)
      File "/usr/local/lib/python2.7/dist-packages/octavia_tempest_plugin/tests/waiters.py", line 78, in wait_for_status
        raise exceptions.UnexpectedResponseCode(message)
    tempest.lib.exceptions.UnexpectedResponseCode: Unexpected response code received
    Details: (AmphoraScenarioTest:setUpClass) show_loadbalancer provisioning_status updated to an invalid state of ERROR
    
{4} setUpClass (octavia_tempest_plugin.tests.scenario.v2.test_member.MemberScenarioTest) [0.000000s] ... FAILED

Captured traceback:
~~~~~~~~~~~~~~~~~~~
    Traceback (most recent call last):
      File "/usr/local/lib/python2.7/dist-packages/tempest/test.py", line 172, in setUpClass
        six.reraise(etype, value, trace)
      File "/usr/local/lib/python2.7/dist-packages/tempest/test.py", line 165, in setUpClass
        cls.resource_setup()
      File "/usr/local/lib/python2.7/dist-packages/octavia_tempest_plugin/tests/scenario/v2/test_member.py", line 52, in resource_setup
        CONF.load_balancer.lb_build_timeout)
      File "/usr/local/lib/python2.7/dist-packages/octavia_tempest_plugin/tests/waiters.py", line 78, in wait_for_status
        raise exceptions.UnexpectedResponseCode(message)
    tempest.lib.exceptions.UnexpectedResponseCode: Unexpected response code received
    Details: (MemberScenarioTest:setUpClass) show_loadbalancer provisioning_status updated to an invalid state of ERROR
    
{2} octavia_tempest_plugin.tests.scenario.v2.test_l7policy.L7PolicyScenarioTest.test_l7policy_CRUD [16.243562s] ... ok
{1} octavia_tempest_plugin.tests.scenario.v2.test_load_balancer.LoadBalancerScenarioTest.test_load_balancer_ipv4_CRUD [92.199353s] ... ok
{0} octavia_tempest_plugin.tests.scenario.v2.test_healthmonitor.HealthMonitorScenarioTest.test_healthmonitor_CRUD [15.851469s] ... ok
{1} octavia_tempest_plugin.tests.scenario.v2.test_load_balancer.LoadBalancerScenarioTest.test_load_balancer_ipv6_CRUD [71.908306s] ... FAILED

Captured traceback:
~~~~~~~~~~~~~~~~~~~
    Traceback (most recent call last):
      File "/usr/local/lib/python2.7/dist-packages/octavia_tempest_plugin/tests/scenario/v2/test_load_balancer.py", line 41, in test_load_balancer_ipv6_CRUD
        self._test_load_balancer_CRUD(6)
      File "/usr/local/lib/python2.7/dist-packages/octavia_tempest_plugin/tests/scenario/v2/test_load_balancer.py", line 70, in _test_load_balancer_CRUD
        CONF.load_balancer.lb_build_timeout)
      File "/usr/local/lib/python2.7/dist-packages/octavia_tempest_plugin/tests/waiters.py", line 78, in wait_for_status
        raise exceptions.UnexpectedResponseCode(message)
    tempest.lib.exceptions.UnexpectedResponseCode: Unexpected response code received
    Details: (LoadBalancerScenarioTest:test_load_balancer_ipv6_CRUD) show_loadbalancer provisioning_status updated to an invalid state of ERROR
    

Captured pythonlogging:
~~~~~~~~~~~~~~~~~~~~~~~
    2018-08-21 05:36:55,791 42201 INFO     [tempest.lib.common.rest_client] Request (LoadBalancerScenarioTest:test_load_balancer_ipv6_CRUD): 201 POST https://172.21.0.199:9876/v2.0/lbaas/loadbalancers 1.556s
    2018-08-21 05:36:55,792 42201 INFO     [octavia_tempest_plugin.tests.waiters] Waiting for show_loadbalancer status to update to ACTIVE
    2018-08-21 05:36:55,831 42201 INFO     [tempest.lib.common.rest_client] Request (LoadBalancerScenarioTest:test_load_balancer_ipv6_CRUD): 200 GET https://172.21.0.199:9876/v2.0/lbaas/loadbalancers/14bbcdbc-ffa7-4c5f-926d-cb99f1ad88d1 0.038s
    2018-08-21 05:37:05,870 42201 INFO     [tempest.lib.common.rest_client] Request (LoadBalancerScenarioTest:test_load_balancer_ipv6_CRUD): 200 GET https://172.21.0.199:9876/v2.0/lbaas/loadbalancers/14bbcdbc-ffa7-4c5f-926d-cb99f1ad88d1 0.031s
    2018-08-21 05:37:15,916 42201 INFO     [tempest.lib.common.rest_client] Request (LoadBalancerScenarioTest:test_load_balancer_ipv6_CRUD): 200 GET https://172.21.0.199:9876/v2.0/lbaas/loadbalancers/14bbcdbc-ffa7-4c5f-926d-cb99f1ad88d1 0.034s
    2018-08-21 05:37:25,952 42201 INFO     [tempest.lib.common.rest_client] Request (LoadBalancerScenarioTest:test_load_balancer_ipv6_CRUD): 200 GET https://172.21.0.199:9876/v2.0/lbaas/loadbalancers/14bbcdbc-ffa7-4c5f-926d-cb99f1ad88d1 0.033s
    2018-08-21 05:37:36,005 42201 INFO     [tempest.lib.common.rest_client] Request (LoadBalancerScenarioTest:test_load_balancer_ipv6_CRUD): 200 GET https://172.21.0.199:9876/v2.0/lbaas/loadbalancers/14bbcdbc-ffa7-4c5f-926d-cb99f1ad88d1 0.042s
    2018-08-21 05:37:46,048 42201 INFO     [tempest.lib.common.rest_client] Request (LoadBalancerScenarioTest:test_load_balancer_ipv6_CRUD): 200 GET https://172.21.0.199:9876/v2.0/lbaas/loadbalancers/14bbcdbc-ffa7-4c5f-926d-cb99f1ad88d1 0.031s
    2018-08-21 05:37:56,084 42201 INFO     [tempest.lib.common.rest_client] Request (LoadBalancerScenarioTest:test_load_balancer_ipv6_CRUD): 200 GET https://172.21.0.199:9876/v2.0/lbaas/loadbalancers/14bbcdbc-ffa7-4c5f-926d-cb99f1ad88d1 0.033s
    2018-08-21 05:38:06,137 42201 INFO     [tempest.lib.common.rest_client] Request (LoadBalancerScenarioTest:test_load_balancer_ipv6_CRUD): 200 GET https://172.21.0.199:9876/v2.0/lbaas/loadbalancers/14bbcdbc-ffa7-4c5f-926d-cb99f1ad88d1 0.042s
    
{2} setUpClass (octavia_tempest_plugin.tests.scenario.v2.test_pool.PoolScenarioTest) [0.000000s] ... FAILED

Captured traceback:
~~~~~~~~~~~~~~~~~~~
    Traceback (most recent call last):
      File "/usr/local/lib/python2.7/dist-packages/tempest/test.py", line 172, in setUpClass
        six.reraise(etype, value, trace)
      File "/usr/local/lib/python2.7/dist-packages/tempest/test.py", line 165, in setUpClass
        cls.resource_setup()
      File "/usr/local/lib/python2.7/dist-packages/octavia_tempest_plugin/tests/scenario/v2/test_pool.py", line 52, in resource_setup
        CONF.load_balancer.lb_build_timeout)
      File "/usr/local/lib/python2.7/dist-packages/octavia_tempest_plugin/tests/waiters.py", line 78, in wait_for_status
        raise exceptions.UnexpectedResponseCode(message)
    tempest.lib.exceptions.UnexpectedResponseCode: Unexpected response code received
    Details: (PoolScenarioTest:setUpClass) show_loadbalancer provisioning_status updated to an invalid state of ERROR
    
{3} setUpClass (octavia_tempest_plugin.tests.scenario.v2.test_traffic_ops.TrafficOperationsScenarioTest) [0.000000s] ... FAILED

Captured traceback:
~~~~~~~~~~~~~~~~~~~
    Traceback (most recent call last):
      File "/usr/local/lib/python2.7/dist-packages/tempest/test.py", line 172, in setUpClass
        six.reraise(etype, value, trace)
      File "/usr/local/lib/python2.7/dist-packages/tempest/test.py", line 165, in setUpClass
        cls.resource_setup()
      File "/usr/local/lib/python2.7/dist-packages/octavia_tempest_plugin/tests/scenario/v2/test_traffic_ops.py", line 38, in resource_setup
        super(TrafficOperationsScenarioTest, cls).resource_setup()
      File "/usr/local/lib/python2.7/dist-packages/octavia_tempest_plugin/tests/test_base.py", line 519, in resource_setup
        cls.webserver1_response)
      File "/usr/local/lib/python2.7/dist-packages/octavia_tempest_plugin/tests/test_base.py", line 679, in _install_start_webserver
        linux_client.validate_authentication()
      File "/usr/local/lib/python2.7/dist-packages/tempest/lib/common/utils/linux/remote_client.py", line 60, in wrapper
        six.reraise(*original_exception)
      File "/usr/local/lib/python2.7/dist-packages/tempest/lib/common/utils/linux/remote_client.py", line 33, in wrapper
        return function(self, *args, **kwargs)
      File "/usr/local/lib/python2.7/dist-packages/tempest/lib/common/utils/linux/remote_client.py", line 116, in validate_authentication
        self.ssh_client.test_connection_auth()
      File "/usr/local/lib/python2.7/dist-packages/tempest/lib/common/ssh.py", line 207, in test_connection_auth
        connection = self._get_ssh_connection()
      File "/usr/local/lib/python2.7/dist-packages/tempest/lib/common/ssh.py", line 121, in _get_ssh_connection
        password=self.password)
    tempest.lib.exceptions.SSHTimeout: Connection to the 10.2.1.10 via SSH timed out.
    User: ubuntu, Password: None
    

==============================
Failed 7 tests - output below:
==============================

setUpClass (octavia_tempest_plugin.tests.scenario.v2.test_listener.ListenerScenarioTest)
----------------------------------------------------------------------------------------

Captured traceback:
~~~~~~~~~~~~~~~~~~~
    Traceback (most recent call last):
      File "/usr/local/lib/python2.7/dist-packages/tempest/test.py", line 172, in setUpClass
        six.reraise(etype, value, trace)
      File "/usr/local/lib/python2.7/dist-packages/tempest/test.py", line 165, in setUpClass
        cls.resource_setup()
      File "/usr/local/lib/python2.7/dist-packages/octavia_tempest_plugin/tests/scenario/v2/test_listener.py", line 53, in resource_setup
        CONF.load_balancer.lb_build_timeout)
      File "/usr/local/lib/python2.7/dist-packages/octavia_tempest_plugin/tests/waiters.py", line 78, in wait_for_status
        raise exceptions.UnexpectedResponseCode(message)
    tempest.lib.exceptions.UnexpectedResponseCode: Unexpected response code received
    Details: (ListenerScenarioTest:setUpClass) show_loadbalancer provisioning_status updated to an invalid state of ERROR
    

setUpClass (octavia_tempest_plugin.tests.scenario.v2.test_l7rule.L7RuleScenarioTest)
------------------------------------------------------------------------------------

Captured traceback:
~~~~~~~~~~~~~~~~~~~
    Traceback (most recent call last):
      File "/usr/local/lib/python2.7/dist-packages/tempest/test.py", line 172, in setUpClass
        six.reraise(etype, value, trace)
      File "/usr/local/lib/python2.7/dist-packages/tempest/test.py", line 165, in setUpClass
        cls.resource_setup()
      File "/usr/local/lib/python2.7/dist-packages/octavia_tempest_plugin/tests/scenario/v2/test_l7rule.py", line 52, in resource_setup
        CONF.load_balancer.lb_build_timeout)
      File "/usr/local/lib/python2.7/dist-packages/octavia_tempest_plugin/tests/waiters.py", line 78, in wait_for_status
        raise exceptions.UnexpectedResponseCode(message)
    tempest.lib.exceptions.UnexpectedResponseCode: Unexpected response code received
    Details: (L7RuleScenarioTest:setUpClass) show_loadbalancer provisioning_status updated to an invalid state of ERROR
    

setUpClass (octavia_tempest_plugin.tests.scenario.v2.test_amphora.AmphoraScenarioTest)
--------------------------------------------------------------------------------------

Captured traceback:
~~~~~~~~~~~~~~~~~~~
    Traceback (most recent call last):
      File "/usr/local/lib/python2.7/dist-packages/tempest/test.py", line 172, in setUpClass
        six.reraise(etype, value, trace)
      File "/usr/local/lib/python2.7/dist-packages/tempest/test.py", line 165, in setUpClass
        cls.resource_setup()
      File "/usr/local/lib/python2.7/dist-packages/octavia_tempest_plugin/tests/scenario/v2/test_amphora.py", line 54, in resource_setup
        CONF.load_balancer.lb_build_timeout)
      File "/usr/local/lib/python2.7/dist-packages/octavia_tempest_plugin/tests/waiters.py", line 78, in wait_for_status
        raise exceptions.UnexpectedResponseCode(message)
    tempest.lib.exceptions.UnexpectedResponseCode: Unexpected response code received
    Details: (AmphoraScenarioTest:setUpClass) show_loadbalancer provisioning_status updated to an invalid state of ERROR
    

setUpClass (octavia_tempest_plugin.tests.scenario.v2.test_member.MemberScenarioTest)
------------------------------------------------------------------------------------

Captured traceback:
~~~~~~~~~~~~~~~~~~~
    Traceback (most recent call last):
      File "/usr/local/lib/python2.7/dist-packages/tempest/test.py", line 172, in setUpClass
        six.reraise(etype, value, trace)
      File "/usr/local/lib/python2.7/dist-packages/tempest/test.py", line 165, in setUpClass
        cls.resource_setup()
      File "/usr/local/lib/python2.7/dist-packages/octavia_tempest_plugin/tests/scenario/v2/test_member.py", line 52, in resource_setup
        CONF.load_balancer.lb_build_timeout)
      File "/usr/local/lib/python2.7/dist-packages/octavia_tempest_plugin/tests/waiters.py", line 78, in wait_for_status
        raise exceptions.UnexpectedResponseCode(message)
    tempest.lib.exceptions.UnexpectedResponseCode: Unexpected response code received
    Details: (MemberScenarioTest:setUpClass) show_loadbalancer provisioning_status updated to an invalid state of ERROR
    

octavia_tempest_plugin.tests.scenario.v2.test_load_balancer.LoadBalancerScenarioTest.test_load_balancer_ipv6_CRUD[id-86ffecc4-dce8-46f9-936e-8a4c6bcf3959]
----------------------------------------------------------------------------------------------------------------------------------------------------------

Captured traceback:
~~~~~~~~~~~~~~~~~~~
    Traceback (most recent call last):
      File "/usr/local/lib/python2.7/dist-packages/octavia_tempest_plugin/tests/scenario/v2/test_load_balancer.py", line 41, in test_load_balancer_ipv6_CRUD
        self._test_load_balancer_CRUD(6)
      File "/usr/local/lib/python2.7/dist-packages/octavia_tempest_plugin/tests/scenario/v2/test_load_balancer.py", line 70, in _test_load_balancer_CRUD
        CONF.load_balancer.lb_build_timeout)
      File "/usr/local/lib/python2.7/dist-packages/octavia_tempest_plugin/tests/waiters.py", line 78, in wait_for_status
        raise exceptions.UnexpectedResponseCode(message)
    tempest.lib.exceptions.UnexpectedResponseCode: Unexpected response code received
    Details: (LoadBalancerScenarioTest:test_load_balancer_ipv6_CRUD) show_loadbalancer provisioning_status updated to an invalid state of ERROR
    

Captured pythonlogging:
~~~~~~~~~~~~~~~~~~~~~~~
    2018-08-21 05:36:55,791 42201 INFO     [tempest.lib.common.rest_client] Request (LoadBalancerScenarioTest:test_load_balancer_ipv6_CRUD): 201 POST https://172.21.0.199:9876/v2.0/lbaas/loadbalancers 1.556s
    2018-08-21 05:36:55,792 42201 INFO     [octavia_tempest_plugin.tests.waiters] Waiting for show_loadbalancer status to update to ACTIVE
    2018-08-21 05:36:55,831 42201 INFO     [tempest.lib.common.rest_client] Request (LoadBalancerScenarioTest:test_load_balancer_ipv6_CRUD): 200 GET https://172.21.0.199:9876/v2.0/lbaas/loadbalancers/14bbcdbc-ffa7-4c5f-926d-cb99f1ad88d1 0.038s
    2018-08-21 05:37:05,870 42201 INFO     [tempest.lib.common.rest_client] Request (LoadBalancerScenarioTest:test_load_balancer_ipv6_CRUD): 200 GET https://172.21.0.199:9876/v2.0/lbaas/loadbalancers/14bbcdbc-ffa7-4c5f-926d-cb99f1ad88d1 0.031s
    2018-08-21 05:37:15,916 42201 INFO     [tempest.lib.common.rest_client] Request (LoadBalancerScenarioTest:test_load_balancer_ipv6_CRUD): 200 GET https://172.21.0.199:9876/v2.0/lbaas/loadbalancers/14bbcdbc-ffa7-4c5f-926d-cb99f1ad88d1 0.034s
    2018-08-21 05:37:25,952 42201 INFO     [tempest.lib.common.rest_client] Request (LoadBalancerScenarioTest:test_load_balancer_ipv6_CRUD): 200 GET https://172.21.0.199:9876/v2.0/lbaas/loadbalancers/14bbcdbc-ffa7-4c5f-926d-cb99f1ad88d1 0.033s
    2018-08-21 05:37:36,005 42201 INFO     [tempest.lib.common.rest_client] Request (LoadBalancerScenarioTest:test_load_balancer_ipv6_CRUD): 200 GET https://172.21.0.199:9876/v2.0/lbaas/loadbalancers/14bbcdbc-ffa7-4c5f-926d-cb99f1ad88d1 0.042s
    2018-08-21 05:37:46,048 42201 INFO     [tempest.lib.common.rest_client] Request (LoadBalancerScenarioTest:test_load_balancer_ipv6_CRUD): 200 GET https://172.21.0.199:9876/v2.0/lbaas/loadbalancers/14bbcdbc-ffa7-4c5f-926d-cb99f1ad88d1 0.031s
    2018-08-21 05:37:56,084 42201 INFO     [tempest.lib.common.rest_client] Request (LoadBalancerScenarioTest:test_load_balancer_ipv6_CRUD): 200 GET https://172.21.0.199:9876/v2.0/lbaas/loadbalancers/14bbcdbc-ffa7-4c5f-926d-cb99f1ad88d1 0.033s
    2018-08-21 05:38:06,137 42201 INFO     [tempest.lib.common.rest_client] Request (LoadBalancerScenarioTest:test_load_balancer_ipv6_CRUD): 200 GET https://172.21.0.199:9876/v2.0/lbaas/loadbalancers/14bbcdbc-ffa7-4c5f-926d-cb99f1ad88d1 0.042s
    

setUpClass (octavia_tempest_plugin.tests.scenario.v2.test_pool.PoolScenarioTest)
--------------------------------------------------------------------------------

Captured traceback:
~~~~~~~~~~~~~~~~~~~
    Traceback (most recent call last):
      File "/usr/local/lib/python2.7/dist-packages/tempest/test.py", line 172, in setUpClass
        six.reraise(etype, value, trace)
      File "/usr/local/lib/python2.7/dist-packages/tempest/test.py", line 165, in setUpClass
        cls.resource_setup()
      File "/usr/local/lib/python2.7/dist-packages/octavia_tempest_plugin/tests/scenario/v2/test_pool.py", line 52, in resource_setup
        CONF.load_balancer.lb_build_timeout)
      File "/usr/local/lib/python2.7/dist-packages/octavia_tempest_plugin/tests/waiters.py", line 78, in wait_for_status
        raise exceptions.UnexpectedResponseCode(message)
    tempest.lib.exceptions.UnexpectedResponseCode: Unexpected response code received
    Details: (PoolScenarioTest:setUpClass) show_loadbalancer provisioning_status updated to an invalid state of ERROR
    

setUpClass (octavia_tempest_plugin.tests.scenario.v2.test_traffic_ops.TrafficOperationsScenarioTest)
----------------------------------------------------------------------------------------------------

Captured traceback:
~~~~~~~~~~~~~~~~~~~
    Traceback (most recent call last):
      File "/usr/local/lib/python2.7/dist-packages/tempest/test.py", line 172, in setUpClass
        six.reraise(etype, value, trace)
      File "/usr/local/lib/python2.7/dist-packages/tempest/test.py", line 165, in setUpClass
        cls.resource_setup()
      File "/usr/local/lib/python2.7/dist-packages/octavia_tempest_plugin/tests/scenario/v2/test_traffic_ops.py", line 38, in resource_setup
        super(TrafficOperationsScenarioTest, cls).resource_setup()
      File "/usr/local/lib/python2.7/dist-packages/octavia_tempest_plugin/tests/test_base.py", line 519, in resource_setup
        cls.webserver1_response)
      File "/usr/local/lib/python2.7/dist-packages/octavia_tempest_plugin/tests/test_base.py", line 679, in _install_start_webserver
        linux_client.validate_authentication()
      File "/usr/local/lib/python2.7/dist-packages/tempest/lib/common/utils/linux/remote_client.py", line 60, in wrapper
        six.reraise(*original_exception)
      File "/usr/local/lib/python2.7/dist-packages/tempest/lib/common/utils/linux/remote_client.py", line 33, in wrapper
        return function(self, *args, **kwargs)
      File "/usr/local/lib/python2.7/dist-packages/tempest/lib/common/utils/linux/remote_client.py", line 116, in validate_authentication
        self.ssh_client.test_connection_auth()
      File "/usr/local/lib/python2.7/dist-packages/tempest/lib/common/ssh.py", line 207, in test_connection_auth
        connection = self._get_ssh_connection()
      File "/usr/local/lib/python2.7/dist-packages/tempest/lib/common/ssh.py", line 121, in _get_ssh_connection
        password=self.password)
    tempest.lib.exceptions.SSHTimeout: Connection to the 10.2.1.10 via SSH timed out.
    User: ubuntu, Password: None
    


======
Totals
======
Ran: 10 tests in 1260.0000 sec.
 - Passed: 3
 - Skipped: 0
 - Expected Fail: 0
 - Unexpected Success: 0
 - Failed: 7
Sum of execute time for each test: 196.2027 sec.

==============
Worker Balance
==============
 - Worker 0 (2 tests) => 0:01:53.330986
 - Worker 1 (3 tests) => 0:02:54.949156
 - Worker 2 (2 tests) => 0:02:53.481249
 - Worker 3 (2 tests) => 0:08:00.241794
 - Worker 4 (1 tests) => 0:00:00
